[2023-11-02T20:22:23.501+0000] {taskinstance.py:1159} INFO - Dependencies all met for dep_context=non-requeueable deps ti=<TaskInstance: pinecone_data_pipeline_with_params.load_csv_into_pinecone manual__2023-11-02T20:20:59+00:00 [queued]>
[2023-11-02T20:22:23.506+0000] {taskinstance.py:1159} INFO - Dependencies all met for dep_context=requeueable deps ti=<TaskInstance: pinecone_data_pipeline_with_params.load_csv_into_pinecone manual__2023-11-02T20:20:59+00:00 [queued]>
[2023-11-02T20:22:23.507+0000] {taskinstance.py:1361} INFO - Starting attempt 2 of 2
[2023-11-02T20:22:23.514+0000] {taskinstance.py:1382} INFO - Executing <Task(PythonOperator): load_csv_into_pinecone> on 2023-11-02 20:20:59+00:00
[2023-11-02T20:22:23.520+0000] {standard_task_runner.py:57} INFO - Started process 1395 to run task
[2023-11-02T20:22:23.522+0000] {standard_task_runner.py:84} INFO - Running: ['***', 'tasks', 'run', 'pinecone_data_pipeline_with_params', 'load_csv_into_pinecone', 'manual__2023-11-02T20:20:59+00:00', '--job-id', '49', '--raw', '--subdir', 'DAGS_FOLDER/sandbox.py', '--cfg-path', '/tmp/tmp43bjj0y2']
[2023-11-02T20:22:23.528+0000] {standard_task_runner.py:85} INFO - Job 49: Subtask load_csv_into_pinecone
[2023-11-02T20:22:23.562+0000] {task_command.py:416} INFO - Running <TaskInstance: pinecone_data_pipeline_with_params.load_csv_into_pinecone manual__2023-11-02T20:20:59+00:00 [running]> on host 41d83c49b4dc
[2023-11-02T20:22:23.608+0000] {taskinstance.py:1662} INFO - Exporting env vars: AIRFLOW_CTX_DAG_OWNER='***' AIRFLOW_CTX_DAG_ID='pinecone_data_pipeline_with_params' AIRFLOW_CTX_TASK_ID='load_csv_into_pinecone' AIRFLOW_CTX_EXECUTION_DATE='2023-11-02T20:20:59+00:00' AIRFLOW_CTX_TRY_NUMBER='2' AIRFLOW_CTX_DAG_RUN_ID='manual__2023-11-02T20:20:59+00:00'
[2023-11-02T20:22:23.930+0000] {taskinstance.py:1937} ERROR - Task failed with exception
Traceback (most recent call last):
  File "/home/airflow/.local/lib/python3.8/site-packages/airflow/operators/python.py", line 192, in execute
    return_value = self.execute_callable()
  File "/home/airflow/.local/lib/python3.8/site-packages/airflow/operators/python.py", line 209, in execute_callable
    return self.python_callable(*self.op_args, **self.op_kwargs)
  File "/opt/airflow/dags/sandbox.py", line 35, in load_csv_into_pinecone
    df = pd.read_csv(source_path)
  File "/home/airflow/.local/lib/python3.8/site-packages/pandas/io/parsers/readers.py", line 912, in read_csv
    return _read(filepath_or_buffer, kwds)
  File "/home/airflow/.local/lib/python3.8/site-packages/pandas/io/parsers/readers.py", line 577, in _read
    parser = TextFileReader(filepath_or_buffer, **kwds)
  File "/home/airflow/.local/lib/python3.8/site-packages/pandas/io/parsers/readers.py", line 1407, in __init__
    self._engine = self._make_engine(f, self.engine)
  File "/home/airflow/.local/lib/python3.8/site-packages/pandas/io/parsers/readers.py", line 1661, in _make_engine
    self.handles = get_handle(
  File "/home/airflow/.local/lib/python3.8/site-packages/pandas/io/common.py", line 716, in get_handle
    ioargs = _get_filepath_or_buffer(
  File "/home/airflow/.local/lib/python3.8/site-packages/pandas/io/common.py", line 456, in _get_filepath_or_buffer
    raise ValueError(msg)
ValueError: Invalid file path or buffer object type: <class '***.models.param.Param'>
[2023-11-02T20:22:23.956+0000] {taskinstance.py:1400} INFO - Marking task as FAILED. dag_id=pinecone_data_pipeline_with_params, task_id=load_csv_into_pinecone, execution_date=20231102T202059, start_date=20231102T202223, end_date=20231102T202223
[2023-11-02T20:22:23.967+0000] {standard_task_runner.py:104} ERROR - Failed to execute job 49 for task load_csv_into_pinecone (Invalid file path or buffer object type: <class '***.models.param.Param'>; 1395)
[2023-11-02T20:22:24.003+0000] {local_task_job_runner.py:228} INFO - Task exited with return code 1
[2023-11-02T20:22:24.019+0000] {taskinstance.py:2778} INFO - 0 downstream tasks scheduled from follow-on schedule check
