[2023-11-03T01:08:19.996+0000] {taskinstance.py:1159} INFO - Dependencies all met for dep_context=non-requeueable deps ti=<TaskInstance: pinecone_data_pipeline_with_params.load_csv_into_pinecone manual__2023-11-03T01:08:14+00:00 [queued]>
[2023-11-03T01:08:20.002+0000] {taskinstance.py:1159} INFO - Dependencies all met for dep_context=requeueable deps ti=<TaskInstance: pinecone_data_pipeline_with_params.load_csv_into_pinecone manual__2023-11-03T01:08:14+00:00 [queued]>
[2023-11-03T01:08:20.003+0000] {taskinstance.py:1361} INFO - Starting attempt 1 of 2
[2023-11-03T01:08:20.011+0000] {taskinstance.py:1382} INFO - Executing <Task(PythonOperator): load_csv_into_pinecone> on 2023-11-03 01:08:14+00:00
[2023-11-03T01:08:20.017+0000] {standard_task_runner.py:57} INFO - Started process 763 to run task
[2023-11-03T01:08:20.021+0000] {standard_task_runner.py:84} INFO - Running: ['***', 'tasks', 'run', 'pinecone_data_pipeline_with_params', 'load_csv_into_pinecone', 'manual__2023-11-03T01:08:14+00:00', '--job-id', '72', '--raw', '--subdir', 'DAGS_FOLDER/sandbox.py', '--cfg-path', '/tmp/tmp7e78c2xl']
[2023-11-03T01:08:20.029+0000] {standard_task_runner.py:85} INFO - Job 72: Subtask load_csv_into_pinecone
[2023-11-03T01:08:20.073+0000] {task_command.py:416} INFO - Running <TaskInstance: pinecone_data_pipeline_with_params.load_csv_into_pinecone manual__2023-11-03T01:08:14+00:00 [running]> on host f075beee9797
[2023-11-03T01:08:20.121+0000] {taskinstance.py:1662} INFO - Exporting env vars: AIRFLOW_CTX_DAG_OWNER='***' AIRFLOW_CTX_DAG_ID='pinecone_data_pipeline_with_params' AIRFLOW_CTX_TASK_ID='load_csv_into_pinecone' AIRFLOW_CTX_EXECUTION_DATE='2023-11-03T01:08:14+00:00' AIRFLOW_CTX_TRY_NUMBER='1' AIRFLOW_CTX_DAG_RUN_ID='manual__2023-11-03T01:08:14+00:00'
[2023-11-03T01:08:20.332+0000] {taskinstance.py:1937} ERROR - Task failed with exception
Traceback (most recent call last):
  File "/home/airflow/.local/lib/python3.8/site-packages/airflow/operators/python.py", line 192, in execute
    return_value = self.execute_callable()
  File "/home/airflow/.local/lib/python3.8/site-packages/airflow/operators/python.py", line 209, in execute_callable
    return self.python_callable(*self.op_args, **self.op_kwargs)
  File "/opt/airflow/dags/sandbox.py", line 60, in load_csv_into_pinecone
    upsert_requests = df.apply(row_to_upsert_request, axis=1).tolist()
  File "/home/airflow/.local/lib/python3.8/site-packages/pandas/core/frame.py", line 9423, in apply
    return op.apply().__finalize__(self, method="apply")
  File "/home/airflow/.local/lib/python3.8/site-packages/pandas/core/apply.py", line 678, in apply
    return self.apply_standard()
  File "/home/airflow/.local/lib/python3.8/site-packages/pandas/core/apply.py", line 798, in apply_standard
    results, res_index = self.apply_series_generator()
  File "/home/airflow/.local/lib/python3.8/site-packages/pandas/core/apply.py", line 814, in apply_series_generator
    results[i] = self.f(v)
  File "/opt/airflow/dags/sandbox.py", line 55, in row_to_upsert_request
    metadata = {field: row[field] for field in metadata_fields}
  File "/opt/airflow/dags/sandbox.py", line 55, in <dictcomp>
    metadata = {field: row[field] for field in metadata_fields}
  File "/home/airflow/.local/lib/python3.8/site-packages/pandas/core/series.py", line 993, in __getitem__
    check_dict_or_set_indexers(key)
  File "/home/airflow/.local/lib/python3.8/site-packages/pandas/core/indexing.py", line 2627, in check_dict_or_set_indexers
    raise TypeError(
TypeError: Passing a dict as an indexer is not supported. Use a list instead.
[2023-11-03T01:08:20.351+0000] {taskinstance.py:1400} INFO - Marking task as UP_FOR_RETRY. dag_id=pinecone_data_pipeline_with_params, task_id=load_csv_into_pinecone, execution_date=20231103T010814, start_date=20231103T010819, end_date=20231103T010820
[2023-11-03T01:08:20.360+0000] {standard_task_runner.py:104} ERROR - Failed to execute job 72 for task load_csv_into_pinecone (Passing a dict as an indexer is not supported. Use a list instead.; 763)
[2023-11-03T01:08:20.406+0000] {local_task_job_runner.py:228} INFO - Task exited with return code 1
[2023-11-03T01:08:20.426+0000] {taskinstance.py:2778} INFO - 0 downstream tasks scheduled from follow-on schedule check
