[2023-11-02T23:31:41.293+0000] {taskinstance.py:1159} INFO - Dependencies all met for dep_context=non-requeueable deps ti=<TaskInstance: pinecone_data_pipeline_with_params.load_csv_into_pinecone manual__2023-11-02T23:31:02+00:00 [queued]>
[2023-11-02T23:31:41.298+0000] {taskinstance.py:1159} INFO - Dependencies all met for dep_context=requeueable deps ti=<TaskInstance: pinecone_data_pipeline_with_params.load_csv_into_pinecone manual__2023-11-02T23:31:02+00:00 [queued]>
[2023-11-02T23:31:41.299+0000] {taskinstance.py:1361} INFO - Starting attempt 1 of 2
[2023-11-02T23:31:41.307+0000] {taskinstance.py:1382} INFO - Executing <Task(PythonOperator): load_csv_into_pinecone> on 2023-11-02 23:31:02+00:00
[2023-11-02T23:31:41.313+0000] {standard_task_runner.py:57} INFO - Started process 264 to run task
[2023-11-02T23:31:41.316+0000] {standard_task_runner.py:84} INFO - Running: ['***', 'tasks', 'run', 'pinecone_data_pipeline_with_params', 'load_csv_into_pinecone', 'manual__2023-11-02T23:31:02+00:00', '--job-id', '60', '--raw', '--subdir', 'DAGS_FOLDER/sandbox.py', '--cfg-path', '/tmp/tmp08tirj5w']
[2023-11-02T23:31:41.319+0000] {standard_task_runner.py:85} INFO - Job 60: Subtask load_csv_into_pinecone
[2023-11-02T23:31:41.358+0000] {task_command.py:416} INFO - Running <TaskInstance: pinecone_data_pipeline_with_params.load_csv_into_pinecone manual__2023-11-02T23:31:02+00:00 [running]> on host cdf939224839
[2023-11-02T23:31:41.409+0000] {taskinstance.py:1662} INFO - Exporting env vars: AIRFLOW_CTX_DAG_OWNER='***' AIRFLOW_CTX_DAG_ID='pinecone_data_pipeline_with_params' AIRFLOW_CTX_TASK_ID='load_csv_into_pinecone' AIRFLOW_CTX_EXECUTION_DATE='2023-11-02T23:31:02+00:00' AIRFLOW_CTX_TRY_NUMBER='1' AIRFLOW_CTX_DAG_RUN_ID='manual__2023-11-02T23:31:02+00:00'
[2023-11-02T23:31:41.676+0000] {taskinstance.py:1937} ERROR - Task failed with exception
Traceback (most recent call last):
  File "/home/airflow/.local/lib/python3.8/site-packages/airflow/operators/python.py", line 192, in execute
    return_value = self.execute_callable()
  File "/home/airflow/.local/lib/python3.8/site-packages/airflow/operators/python.py", line 209, in execute_callable
    return self.python_callable(*self.op_args, **self.op_kwargs)
  File "/opt/airflow/dags/sandbox.py", line 49, in load_csv_into_pinecone
    upsert_requests = df.apply(row_to_upsert_request, axis=1)
  File "/home/airflow/.local/lib/python3.8/site-packages/pandas/core/frame.py", line 9423, in apply
    return op.apply().__finalize__(self, method="apply")
  File "/home/airflow/.local/lib/python3.8/site-packages/pandas/core/apply.py", line 678, in apply
    return self.apply_standard()
  File "/home/airflow/.local/lib/python3.8/site-packages/pandas/core/apply.py", line 798, in apply_standard
    results, res_index = self.apply_series_generator()
  File "/home/airflow/.local/lib/python3.8/site-packages/pandas/core/apply.py", line 814, in apply_series_generator
    results[i] = self.f(v)
  File "/opt/airflow/dags/sandbox.py", line 45, in row_to_upsert_request
    metadata = {k: row[k] for k in metadata_fields}
  File "/opt/airflow/dags/sandbox.py", line 45, in <dictcomp>
    metadata = {k: row[k] for k in metadata_fields}
  File "/home/airflow/.local/lib/python3.8/site-packages/pandas/core/series.py", line 993, in __getitem__
    check_dict_or_set_indexers(key)
  File "/home/airflow/.local/lib/python3.8/site-packages/pandas/core/indexing.py", line 2627, in check_dict_or_set_indexers
    raise TypeError(
TypeError: Passing a dict as an indexer is not supported. Use a list instead.
[2023-11-02T23:31:41.692+0000] {taskinstance.py:1400} INFO - Marking task as UP_FOR_RETRY. dag_id=pinecone_data_pipeline_with_params, task_id=load_csv_into_pinecone, execution_date=20231102T233102, start_date=20231102T233141, end_date=20231102T233141
[2023-11-02T23:31:41.700+0000] {standard_task_runner.py:104} ERROR - Failed to execute job 60 for task load_csv_into_pinecone (Passing a dict as an indexer is not supported. Use a list instead.; 264)
[2023-11-02T23:31:41.734+0000] {local_task_job_runner.py:228} INFO - Task exited with return code 1
[2023-11-02T23:31:41.752+0000] {taskinstance.py:2778} INFO - 0 downstream tasks scheduled from follow-on schedule check
