[2023-11-02T20:56:17.076+0000] {taskinstance.py:1159} INFO - Dependencies all met for dep_context=non-requeueable deps ti=<TaskInstance: pinecone_data_pipeline_with_params.load_csv_into_pinecone manual__2023-11-02T20:56:10+00:00 [queued]>
[2023-11-02T20:56:17.082+0000] {taskinstance.py:1159} INFO - Dependencies all met for dep_context=requeueable deps ti=<TaskInstance: pinecone_data_pipeline_with_params.load_csv_into_pinecone manual__2023-11-02T20:56:10+00:00 [queued]>
[2023-11-02T20:56:17.083+0000] {taskinstance.py:1361} INFO - Starting attempt 1 of 2
[2023-11-02T20:56:17.091+0000] {taskinstance.py:1382} INFO - Executing <Task(PythonOperator): load_csv_into_pinecone> on 2023-11-02 20:56:10+00:00
[2023-11-02T20:56:17.097+0000] {standard_task_runner.py:57} INFO - Started process 1753 to run task
[2023-11-02T20:56:17.100+0000] {standard_task_runner.py:84} INFO - Running: ['***', 'tasks', 'run', 'pinecone_data_pipeline_with_params', 'load_csv_into_pinecone', 'manual__2023-11-02T20:56:10+00:00', '--job-id', '50', '--raw', '--subdir', 'DAGS_FOLDER/sandbox.py', '--cfg-path', '/tmp/tmpch0byfno']
[2023-11-02T20:56:17.104+0000] {standard_task_runner.py:85} INFO - Job 50: Subtask load_csv_into_pinecone
[2023-11-02T20:56:17.146+0000] {task_command.py:416} INFO - Running <TaskInstance: pinecone_data_pipeline_with_params.load_csv_into_pinecone manual__2023-11-02T20:56:10+00:00 [running]> on host 41d83c49b4dc
[2023-11-02T20:56:17.190+0000] {taskinstance.py:1662} INFO - Exporting env vars: AIRFLOW_CTX_DAG_OWNER='***' AIRFLOW_CTX_DAG_ID='pinecone_data_pipeline_with_params' AIRFLOW_CTX_TASK_ID='load_csv_into_pinecone' AIRFLOW_CTX_EXECUTION_DATE='2023-11-02T20:56:10+00:00' AIRFLOW_CTX_TRY_NUMBER='1' AIRFLOW_CTX_DAG_RUN_ID='manual__2023-11-02T20:56:10+00:00'
[2023-11-02T20:56:17.456+0000] {taskinstance.py:1937} ERROR - Task failed with exception
Traceback (most recent call last):
  File "/home/airflow/.local/lib/python3.8/site-packages/airflow/operators/python.py", line 192, in execute
    return_value = self.execute_callable()
  File "/home/airflow/.local/lib/python3.8/site-packages/airflow/operators/python.py", line 209, in execute_callable
    return self.python_callable(*self.op_args, **self.op_kwargs)
  File "/opt/airflow/dags/sandbox.py", line 38, in load_csv_into_pinecone
    df = pd.read_csv(source_path)
  File "/home/airflow/.local/lib/python3.8/site-packages/pandas/io/parsers/readers.py", line 912, in read_csv
    return _read(filepath_or_buffer, kwds)
  File "/home/airflow/.local/lib/python3.8/site-packages/pandas/io/parsers/readers.py", line 577, in _read
    parser = TextFileReader(filepath_or_buffer, **kwds)
  File "/home/airflow/.local/lib/python3.8/site-packages/pandas/io/parsers/readers.py", line 1407, in __init__
    self._engine = self._make_engine(f, self.engine)
  File "/home/airflow/.local/lib/python3.8/site-packages/pandas/io/parsers/readers.py", line 1661, in _make_engine
    self.handles = get_handle(
  File "/home/airflow/.local/lib/python3.8/site-packages/pandas/io/common.py", line 859, in get_handle
    handle = open(
FileNotFoundError: [Errno 2] No such file or directory: '/Users/saniyakapur/Downloads/ass3/form_embeddings.csv'
[2023-11-02T20:56:17.472+0000] {taskinstance.py:1400} INFO - Marking task as UP_FOR_RETRY. dag_id=pinecone_data_pipeline_with_params, task_id=load_csv_into_pinecone, execution_date=20231102T205610, start_date=20231102T205617, end_date=20231102T205617
[2023-11-02T20:56:17.484+0000] {standard_task_runner.py:104} ERROR - Failed to execute job 50 for task load_csv_into_pinecone ([Errno 2] No such file or directory: '/Users/saniyakapur/Downloads/ass3/form_embeddings.csv'; 1753)
[2023-11-02T20:56:17.528+0000] {local_task_job_runner.py:228} INFO - Task exited with return code 1
[2023-11-02T20:56:17.545+0000] {taskinstance.py:2778} INFO - 0 downstream tasks scheduled from follow-on schedule check
