[2023-11-03T01:40:45.344+0000] {taskinstance.py:1159} INFO - Dependencies all met for dep_context=non-requeueable deps ti=<TaskInstance: pinecone_data_pipeline_with_params.load_csv_into_pinecone manual__2023-11-03T01:40:38+00:00 [queued]>
[2023-11-03T01:40:45.350+0000] {taskinstance.py:1159} INFO - Dependencies all met for dep_context=requeueable deps ti=<TaskInstance: pinecone_data_pipeline_with_params.load_csv_into_pinecone manual__2023-11-03T01:40:38+00:00 [queued]>
[2023-11-03T01:40:45.351+0000] {taskinstance.py:1361} INFO - Starting attempt 1 of 2
[2023-11-03T01:40:45.359+0000] {taskinstance.py:1382} INFO - Executing <Task(PythonOperator): load_csv_into_pinecone> on 2023-11-03 01:40:38+00:00
[2023-11-03T01:40:45.366+0000] {standard_task_runner.py:57} INFO - Started process 1248 to run task
[2023-11-03T01:40:45.369+0000] {standard_task_runner.py:84} INFO - Running: ['***', 'tasks', 'run', 'pinecone_data_pipeline_with_params', 'load_csv_into_pinecone', 'manual__2023-11-03T01:40:38+00:00', '--job-id', '80', '--raw', '--subdir', 'DAGS_FOLDER/sandbox.py', '--cfg-path', '/tmp/tmp8ueqf15u']
[2023-11-03T01:40:45.373+0000] {standard_task_runner.py:85} INFO - Job 80: Subtask load_csv_into_pinecone
[2023-11-03T01:40:45.423+0000] {task_command.py:416} INFO - Running <TaskInstance: pinecone_data_pipeline_with_params.load_csv_into_pinecone manual__2023-11-03T01:40:38+00:00 [running]> on host f075beee9797
[2023-11-03T01:40:45.469+0000] {taskinstance.py:1662} INFO - Exporting env vars: AIRFLOW_CTX_DAG_OWNER='***' AIRFLOW_CTX_DAG_ID='pinecone_data_pipeline_with_params' AIRFLOW_CTX_TASK_ID='load_csv_into_pinecone' AIRFLOW_CTX_EXECUTION_DATE='2023-11-03T01:40:38+00:00' AIRFLOW_CTX_TRY_NUMBER='1' AIRFLOW_CTX_DAG_RUN_ID='manual__2023-11-03T01:40:38+00:00'
[2023-11-03T01:40:56.212+0000] {taskinstance.py:1937} ERROR - Task failed with exception
Traceback (most recent call last):
  File "/home/airflow/.local/lib/python3.8/site-packages/airflow/operators/python.py", line 192, in execute
    return_value = self.execute_callable()
  File "/home/airflow/.local/lib/python3.8/site-packages/airflow/operators/python.py", line 209, in execute_callable
    return self.python_callable(*self.op_args, **self.op_kwargs)
  File "/opt/airflow/dags/sandbox.py", line 52, in load_csv_into_pinecone
    index.upsert(vectors=zip(df.id, df.vector, metadata_fields))
AttributeError: 'NoneType' object has no attribute 'upsert'
[2023-11-03T01:40:56.220+0000] {taskinstance.py:1400} INFO - Marking task as UP_FOR_RETRY. dag_id=pinecone_data_pipeline_with_params, task_id=load_csv_into_pinecone, execution_date=20231103T014038, start_date=20231103T014045, end_date=20231103T014056
[2023-11-03T01:40:56.231+0000] {standard_task_runner.py:104} ERROR - Failed to execute job 80 for task load_csv_into_pinecone ('NoneType' object has no attribute 'upsert'; 1248)
[2023-11-03T01:40:56.263+0000] {local_task_job_runner.py:228} INFO - Task exited with return code 1
[2023-11-03T01:40:56.276+0000] {taskinstance.py:2778} INFO - 0 downstream tasks scheduled from follow-on schedule check
