[2023-11-03T01:26:57.465+0000] {taskinstance.py:1159} INFO - Dependencies all met for dep_context=non-requeueable deps ti=<TaskInstance: pinecone_data_pipeline_with_params.load_csv_into_pinecone manual__2023-11-03T01:26:51+00:00 [queued]>
[2023-11-03T01:26:57.470+0000] {taskinstance.py:1159} INFO - Dependencies all met for dep_context=requeueable deps ti=<TaskInstance: pinecone_data_pipeline_with_params.load_csv_into_pinecone manual__2023-11-03T01:26:51+00:00 [queued]>
[2023-11-03T01:26:57.471+0000] {taskinstance.py:1361} INFO - Starting attempt 1 of 2
[2023-11-03T01:26:57.479+0000] {taskinstance.py:1382} INFO - Executing <Task(PythonOperator): load_csv_into_pinecone> on 2023-11-03 01:26:51+00:00
[2023-11-03T01:26:57.484+0000] {standard_task_runner.py:57} INFO - Started process 1028 to run task
[2023-11-03T01:26:57.487+0000] {standard_task_runner.py:84} INFO - Running: ['***', 'tasks', 'run', 'pinecone_data_pipeline_with_params', 'load_csv_into_pinecone', 'manual__2023-11-03T01:26:51+00:00', '--job-id', '76', '--raw', '--subdir', 'DAGS_FOLDER/sandbox.py', '--cfg-path', '/tmp/tmp43oomasz']
[2023-11-03T01:26:57.491+0000] {standard_task_runner.py:85} INFO - Job 76: Subtask load_csv_into_pinecone
[2023-11-03T01:26:57.532+0000] {task_command.py:416} INFO - Running <TaskInstance: pinecone_data_pipeline_with_params.load_csv_into_pinecone manual__2023-11-03T01:26:51+00:00 [running]> on host f075beee9797
[2023-11-03T01:26:57.581+0000] {taskinstance.py:1662} INFO - Exporting env vars: AIRFLOW_CTX_DAG_OWNER='***' AIRFLOW_CTX_DAG_ID='pinecone_data_pipeline_with_params' AIRFLOW_CTX_TASK_ID='load_csv_into_pinecone' AIRFLOW_CTX_EXECUTION_DATE='2023-11-03T01:26:51+00:00' AIRFLOW_CTX_TRY_NUMBER='1' AIRFLOW_CTX_DAG_RUN_ID='manual__2023-11-03T01:26:51+00:00'
[2023-11-03T01:26:57.719+0000] {taskinstance.py:1937} ERROR - Task failed with exception
Traceback (most recent call last):
  File "/home/airflow/.local/lib/python3.8/site-packages/airflow/operators/python.py", line 192, in execute
    return_value = self.execute_callable()
  File "/home/airflow/.local/lib/python3.8/site-packages/airflow/operators/python.py", line 209, in execute_callable
    return self.python_callable(*self.op_args, **self.op_kwargs)
  File "/opt/airflow/dags/sandbox.py", line 47, in load_csv_into_pinecone
    index = pinecone.create_index(index_name, metric="euclidean")
TypeError: create_index() missing 1 required positional argument: 'dimension'
[2023-11-03T01:26:57.729+0000] {taskinstance.py:1400} INFO - Marking task as UP_FOR_RETRY. dag_id=pinecone_data_pipeline_with_params, task_id=load_csv_into_pinecone, execution_date=20231103T012651, start_date=20231103T012657, end_date=20231103T012657
[2023-11-03T01:26:57.739+0000] {standard_task_runner.py:104} ERROR - Failed to execute job 76 for task load_csv_into_pinecone (create_index() missing 1 required positional argument: 'dimension'; 1028)
[2023-11-03T01:26:57.791+0000] {local_task_job_runner.py:228} INFO - Task exited with return code 1
[2023-11-03T01:26:57.806+0000] {taskinstance.py:2778} INFO - 0 downstream tasks scheduled from follow-on schedule check
