[2023-11-02T19:59:23.021+0000] {taskinstance.py:1159} INFO - Dependencies all met for dep_context=non-requeueable deps ti=<TaskInstance: pinecone_data_pipeline_with_params.manage_pinecone_index manual__2023-11-02T19:58:11+00:00 [queued]>
[2023-11-02T19:59:23.027+0000] {taskinstance.py:1159} INFO - Dependencies all met for dep_context=requeueable deps ti=<TaskInstance: pinecone_data_pipeline_with_params.manage_pinecone_index manual__2023-11-02T19:58:11+00:00 [queued]>
[2023-11-02T19:59:23.028+0000] {taskinstance.py:1361} INFO - Starting attempt 2 of 2
[2023-11-02T19:59:23.036+0000] {taskinstance.py:1382} INFO - Executing <Task(PythonOperator): manage_pinecone_index> on 2023-11-02 19:58:11+00:00
[2023-11-02T19:59:23.040+0000] {standard_task_runner.py:57} INFO - Started process 1011 to run task
[2023-11-02T19:59:23.043+0000] {standard_task_runner.py:84} INFO - Running: ['***', 'tasks', 'run', 'pinecone_data_pipeline_with_params', 'manage_pinecone_index', 'manual__2023-11-02T19:58:11+00:00', '--job-id', '40', '--raw', '--subdir', 'DAGS_FOLDER/sandbox.py', '--cfg-path', '/tmp/tmp98fgrs1i']
[2023-11-02T19:59:23.049+0000] {standard_task_runner.py:85} INFO - Job 40: Subtask manage_pinecone_index
[2023-11-02T19:59:23.082+0000] {task_command.py:416} INFO - Running <TaskInstance: pinecone_data_pipeline_with_params.manage_pinecone_index manual__2023-11-02T19:58:11+00:00 [running]> on host 41d83c49b4dc
[2023-11-02T19:59:23.125+0000] {taskinstance.py:1662} INFO - Exporting env vars: AIRFLOW_CTX_DAG_OWNER='***' AIRFLOW_CTX_DAG_ID='pinecone_data_pipeline_with_params' AIRFLOW_CTX_TASK_ID='manage_pinecone_index' AIRFLOW_CTX_EXECUTION_DATE='2023-11-02T19:58:11+00:00' AIRFLOW_CTX_TRY_NUMBER='2' AIRFLOW_CTX_DAG_RUN_ID='manual__2023-11-02T19:58:11+00:00'
[2023-11-02T19:59:23.130+0000] {taskinstance.py:1937} ERROR - Task failed with exception
Traceback (most recent call last):
  File "/home/airflow/.local/lib/python3.8/site-packages/airflow/operators/python.py", line 192, in execute
    return_value = self.execute_callable()
  File "/home/airflow/.local/lib/python3.8/site-packages/airflow/operators/python.py", line 209, in execute_callable
    return self.python_callable(*self.op_args, **self.op_kwargs)
  File "/opt/airflow/dags/sandbox.py", line 83, in manage_pinecone_index
    if index_name not in pinecone.list_indexes():
  File "/home/airflow/.local/lib/python3.8/site-packages/pinecone/manage.py", line 185, in list_indexes
    response = api_instance.list_indexes()
  File "/home/airflow/.local/lib/python3.8/site-packages/pinecone/core/client/api_client.py", line 776, in __call__
    return self.callable(self, *args, **kwargs)
  File "/home/airflow/.local/lib/python3.8/site-packages/pinecone/core/client/api/index_operations_api.py", line 1130, in __list_indexes
    return self.call_with_http_info(**kwargs)
  File "/home/airflow/.local/lib/python3.8/site-packages/pinecone/core/client/api_client.py", line 787, in call_with_http_info
    _host = self.api_client.configuration.get_host_from_settings(
  File "/home/airflow/.local/lib/python3.8/site-packages/pinecone/core/client/configuration.py", line 478, in get_host_from_settings
    url = url.replace("{" + variable_name + "}", used_value)
TypeError: replace() argument 2 must be str, not Param
[2023-11-02T19:59:23.139+0000] {taskinstance.py:1400} INFO - Marking task as FAILED. dag_id=pinecone_data_pipeline_with_params, task_id=manage_pinecone_index, execution_date=20231102T195811, start_date=20231102T195923, end_date=20231102T195923
[2023-11-02T19:59:23.146+0000] {standard_task_runner.py:104} ERROR - Failed to execute job 40 for task manage_pinecone_index (replace() argument 2 must be str, not Param; 1011)
[2023-11-02T19:59:23.176+0000] {local_task_job_runner.py:228} INFO - Task exited with return code 1
[2023-11-02T19:59:23.193+0000] {taskinstance.py:2778} INFO - 0 downstream tasks scheduled from follow-on schedule check
