[2023-11-02T21:38:28.985+0000] {taskinstance.py:1159} INFO - Dependencies all met for dep_context=non-requeueable deps ti=<TaskInstance: pinecone_data_pipeline_with_params.load_csv_into_pinecone manual__2023-11-02T21:37:10+00:00 [queued]>
[2023-11-02T21:38:28.991+0000] {taskinstance.py:1159} INFO - Dependencies all met for dep_context=requeueable deps ti=<TaskInstance: pinecone_data_pipeline_with_params.load_csv_into_pinecone manual__2023-11-02T21:37:10+00:00 [queued]>
[2023-11-02T21:38:28.992+0000] {taskinstance.py:1361} INFO - Starting attempt 2 of 2
[2023-11-02T21:38:29.002+0000] {taskinstance.py:1382} INFO - Executing <Task(PythonOperator): load_csv_into_pinecone> on 2023-11-02 21:37:10+00:00
[2023-11-02T21:38:29.008+0000] {standard_task_runner.py:57} INFO - Started process 132 to run task
[2023-11-02T21:38:29.010+0000] {standard_task_runner.py:84} INFO - Running: ['***', 'tasks', 'run', 'pinecone_data_pipeline_with_params', 'load_csv_into_pinecone', 'manual__2023-11-02T21:37:10+00:00', '--job-id', '57', '--raw', '--subdir', 'DAGS_FOLDER/sandbox.py', '--cfg-path', '/tmp/tmpov2i3v9x']
[2023-11-02T21:38:29.013+0000] {standard_task_runner.py:85} INFO - Job 57: Subtask load_csv_into_pinecone
[2023-11-02T21:38:29.051+0000] {task_command.py:416} INFO - Running <TaskInstance: pinecone_data_pipeline_with_params.load_csv_into_pinecone manual__2023-11-02T21:37:10+00:00 [running]> on host e4af2c29ff1f
[2023-11-02T21:38:29.101+0000] {taskinstance.py:1662} INFO - Exporting env vars: AIRFLOW_CTX_DAG_OWNER='***' AIRFLOW_CTX_DAG_ID='pinecone_data_pipeline_with_params' AIRFLOW_CTX_TASK_ID='load_csv_into_pinecone' AIRFLOW_CTX_EXECUTION_DATE='2023-11-02T21:37:10+00:00' AIRFLOW_CTX_TRY_NUMBER='2' AIRFLOW_CTX_DAG_RUN_ID='manual__2023-11-02T21:37:10+00:00'
[2023-11-02T21:38:29.274+0000] {taskinstance.py:1937} ERROR - Task failed with exception
Traceback (most recent call last):
  File "/home/airflow/.local/lib/python3.8/site-packages/airflow/operators/python.py", line 192, in execute
    return_value = self.execute_callable()
  File "/home/airflow/.local/lib/python3.8/site-packages/airflow/operators/python.py", line 209, in execute_callable
    return self.python_callable(*self.op_args, **self.op_kwargs)
  File "/opt/airflow/dags/sandbox.py", line 46, in load_csv_into_pinecone
    upsert_requests = df.apply(row_to_upsert_request, axis=1)
  File "/home/airflow/.local/lib/python3.8/site-packages/pandas/core/frame.py", line 9423, in apply
    return op.apply().__finalize__(self, method="apply")
  File "/home/airflow/.local/lib/python3.8/site-packages/pandas/core/apply.py", line 678, in apply
    return self.apply_standard()
  File "/home/airflow/.local/lib/python3.8/site-packages/pandas/core/apply.py", line 798, in apply_standard
    results, res_index = self.apply_series_generator()
  File "/home/airflow/.local/lib/python3.8/site-packages/pandas/core/apply.py", line 814, in apply_series_generator
    results[i] = self.f(v)
  File "/opt/airflow/dags/sandbox.py", line 42, in row_to_upsert_request
    metadata = {k: row[k] for k in metadata_fields}
NameError: name 'metadata_fields' is not defined
[2023-11-02T21:38:29.287+0000] {taskinstance.py:1400} INFO - Marking task as FAILED. dag_id=pinecone_data_pipeline_with_params, task_id=load_csv_into_pinecone, execution_date=20231102T213710, start_date=20231102T213828, end_date=20231102T213829
[2023-11-02T21:38:29.297+0000] {standard_task_runner.py:104} ERROR - Failed to execute job 57 for task load_csv_into_pinecone (name 'metadata_fields' is not defined; 132)
[2023-11-02T21:38:29.350+0000] {local_task_job_runner.py:228} INFO - Task exited with return code 1
[2023-11-02T21:38:29.371+0000] {taskinstance.py:2778} INFO - 0 downstream tasks scheduled from follow-on schedule check
