[2023-11-03T01:25:41.479+0000] {taskinstance.py:1159} INFO - Dependencies all met for dep_context=non-requeueable deps ti=<TaskInstance: pinecone_data_pipeline_with_params.load_csv_into_pinecone manual__2023-11-03T01:24:33+00:00 [queued]>
[2023-11-03T01:25:41.485+0000] {taskinstance.py:1159} INFO - Dependencies all met for dep_context=requeueable deps ti=<TaskInstance: pinecone_data_pipeline_with_params.load_csv_into_pinecone manual__2023-11-03T01:24:33+00:00 [queued]>
[2023-11-03T01:25:41.486+0000] {taskinstance.py:1361} INFO - Starting attempt 2 of 2
[2023-11-03T01:25:41.495+0000] {taskinstance.py:1382} INFO - Executing <Task(PythonOperator): load_csv_into_pinecone> on 2023-11-03 01:24:33+00:00
[2023-11-03T01:25:41.501+0000] {standard_task_runner.py:57} INFO - Started process 1000 to run task
[2023-11-03T01:25:41.504+0000] {standard_task_runner.py:84} INFO - Running: ['***', 'tasks', 'run', 'pinecone_data_pipeline_with_params', 'load_csv_into_pinecone', 'manual__2023-11-03T01:24:33+00:00', '--job-id', '75', '--raw', '--subdir', 'DAGS_FOLDER/sandbox.py', '--cfg-path', '/tmp/tmpgxvph9bx']
[2023-11-03T01:25:41.508+0000] {standard_task_runner.py:85} INFO - Job 75: Subtask load_csv_into_pinecone
[2023-11-03T01:25:41.553+0000] {task_command.py:416} INFO - Running <TaskInstance: pinecone_data_pipeline_with_params.load_csv_into_pinecone manual__2023-11-03T01:24:33+00:00 [running]> on host f075beee9797
[2023-11-03T01:25:41.605+0000] {taskinstance.py:1662} INFO - Exporting env vars: AIRFLOW_CTX_DAG_OWNER='***' AIRFLOW_CTX_DAG_ID='pinecone_data_pipeline_with_params' AIRFLOW_CTX_TASK_ID='load_csv_into_pinecone' AIRFLOW_CTX_EXECUTION_DATE='2023-11-03T01:24:33+00:00' AIRFLOW_CTX_TRY_NUMBER='2' AIRFLOW_CTX_DAG_RUN_ID='manual__2023-11-03T01:24:33+00:00'
[2023-11-03T01:25:41.781+0000] {taskinstance.py:1937} ERROR - Task failed with exception
Traceback (most recent call last):
  File "/home/airflow/.local/lib/python3.8/site-packages/airflow/operators/python.py", line 192, in execute
    return_value = self.execute_callable()
  File "/home/airflow/.local/lib/python3.8/site-packages/airflow/operators/python.py", line 209, in execute_callable
    return self.python_callable(*self.op_args, **self.op_kwargs)
  File "/opt/airflow/dags/sandbox.py", line 47, in load_csv_into_pinecone
    index = pinecone.Index(index_name, metric="euclidean")
TypeError: __init__() got an unexpected keyword argument 'metric'
[2023-11-03T01:25:41.793+0000] {taskinstance.py:1400} INFO - Marking task as FAILED. dag_id=pinecone_data_pipeline_with_params, task_id=load_csv_into_pinecone, execution_date=20231103T012433, start_date=20231103T012541, end_date=20231103T012541
[2023-11-03T01:25:41.802+0000] {standard_task_runner.py:104} ERROR - Failed to execute job 75 for task load_csv_into_pinecone (__init__() got an unexpected keyword argument 'metric'; 1000)
[2023-11-03T01:25:41.845+0000] {local_task_job_runner.py:228} INFO - Task exited with return code 1
[2023-11-03T01:25:41.861+0000] {taskinstance.py:2778} INFO - 0 downstream tasks scheduled from follow-on schedule check
