[2023-11-03T01:32:36.971+0000] {taskinstance.py:1159} INFO - Dependencies all met for dep_context=non-requeueable deps ti=<TaskInstance: pinecone_data_pipeline_with_params.load_csv_into_pinecone manual__2023-11-03T01:32:30+00:00 [queued]>
[2023-11-03T01:32:36.977+0000] {taskinstance.py:1159} INFO - Dependencies all met for dep_context=requeueable deps ti=<TaskInstance: pinecone_data_pipeline_with_params.load_csv_into_pinecone manual__2023-11-03T01:32:30+00:00 [queued]>
[2023-11-03T01:32:36.978+0000] {taskinstance.py:1361} INFO - Starting attempt 1 of 2
[2023-11-03T01:32:36.987+0000] {taskinstance.py:1382} INFO - Executing <Task(PythonOperator): load_csv_into_pinecone> on 2023-11-03 01:32:30+00:00
[2023-11-03T01:32:36.994+0000] {standard_task_runner.py:57} INFO - Started process 1122 to run task
[2023-11-03T01:32:36.997+0000] {standard_task_runner.py:84} INFO - Running: ['***', 'tasks', 'run', 'pinecone_data_pipeline_with_params', 'load_csv_into_pinecone', 'manual__2023-11-03T01:32:30+00:00', '--job-id', '78', '--raw', '--subdir', 'DAGS_FOLDER/sandbox.py', '--cfg-path', '/tmp/tmp_feh_cd8']
[2023-11-03T01:32:37.001+0000] {standard_task_runner.py:85} INFO - Job 78: Subtask load_csv_into_pinecone
[2023-11-03T01:32:37.045+0000] {task_command.py:416} INFO - Running <TaskInstance: pinecone_data_pipeline_with_params.load_csv_into_pinecone manual__2023-11-03T01:32:30+00:00 [running]> on host f075beee9797
[2023-11-03T01:32:37.097+0000] {taskinstance.py:1662} INFO - Exporting env vars: AIRFLOW_CTX_DAG_OWNER='***' AIRFLOW_CTX_DAG_ID='pinecone_data_pipeline_with_params' AIRFLOW_CTX_TASK_ID='load_csv_into_pinecone' AIRFLOW_CTX_EXECUTION_DATE='2023-11-03T01:32:30+00:00' AIRFLOW_CTX_TRY_NUMBER='1' AIRFLOW_CTX_DAG_RUN_ID='manual__2023-11-03T01:32:30+00:00'
[2023-11-03T01:32:47.915+0000] {taskinstance.py:1937} ERROR - Task failed with exception
Traceback (most recent call last):
  File "/home/airflow/.local/lib/python3.8/site-packages/airflow/operators/python.py", line 192, in execute
    return_value = self.execute_callable()
  File "/home/airflow/.local/lib/python3.8/site-packages/airflow/operators/python.py", line 209, in execute_callable
    return self.python_callable(*self.op_args, **self.op_kwargs)
  File "/opt/airflow/dags/sandbox.py", line 52, in load_csv_into_pinecone
    index.upsert(vectors=zip(df.id, df.vector, metadata_fields))
AttributeError: 'NoneType' object has no attribute 'upsert'
[2023-11-03T01:32:47.925+0000] {taskinstance.py:1400} INFO - Marking task as UP_FOR_RETRY. dag_id=pinecone_data_pipeline_with_params, task_id=load_csv_into_pinecone, execution_date=20231103T013230, start_date=20231103T013236, end_date=20231103T013247
[2023-11-03T01:32:47.935+0000] {standard_task_runner.py:104} ERROR - Failed to execute job 78 for task load_csv_into_pinecone ('NoneType' object has no attribute 'upsert'; 1122)
[2023-11-03T01:32:47.982+0000] {local_task_job_runner.py:228} INFO - Task exited with return code 1
[2023-11-03T01:32:47.998+0000] {taskinstance.py:2778} INFO - 0 downstream tasks scheduled from follow-on schedule check
